<?xml version="1.0" encoding="UTF-8"?>
<!-- Generated by org.testng.reporters.JUnitReportReporter -->
<testsuite hostname="Draxayani-PC" name="com.adv.qa.selenium.tests.currency.phase2.A056_AP_Ledger_ControlsTest" tests="1" failures="0" timestamp="5 Sep 2014 09:40:37 GMT" time="239.346" errors="1">
  <testcase name="verify" time="239.346" classname="com.adv.qa.selenium.tests.currency.phase2.A056_AP_Ledger_ControlsTest">
    <error type="java.lang.AssertionError" message="New purchase ledger Company  HC not  created expected [true] but found [false]">
      <![CDATA[java.lang.AssertionError: New purchase ledger Company  HC not  created expected [true] but found [false]
	at org.testng.Assert.fail(Assert.java:94)
	at org.testng.Assert.failNotEquals(Assert.java:494)
	at org.testng.Assert.assertTrue(Assert.java:42)
	at com.adv.qa.selenium.framework.Assert.assertTrue(Assert.java:43)
	at com.adv.qa.selenium.tests.currency.phase2.A056_AP_Ledger_ControlsTest.verify(A056_AP_Ledger_ControlsTest.java:71)
	at sun.reflect.NativeMethodAccessorImpl.invoke0(Native Method)
	at sun.reflect.NativeMethodAccessorImpl.invoke(Unknown Source)
	at sun.reflect.DelegatingMethodAccessorImpl.invoke(Unknown Source)
	at java.lang.reflect.Method.invoke(Unknown Source)
	at org.testng.internal.MethodInvocationHelper.invokeMethod(MethodInvocationHelper.java:84)
	at org.testng.internal.InvokeMethodRunnable.runOne(InvokeMethodRunnable.java:46)
	at org.testng.internal.InvokeMethodRunnable.run(InvokeMethodRunnable.java:37)
	at java.util.concurrent.Executors$RunnableAdapter.call(Unknown Source)
	at java.util.concurrent.FutureTask.run(Unknown Source)
	at java.util.concurrent.ThreadPoolExecutor.runWorker(Unknown Source)
	at java.util.concurrent.ThreadPoolExecutor$Worker.run(Unknown Source)
	at java.lang.Thread.run(Unknown Source)
]]>
    </error>
  </testcase> <!-- verify -->
</testsuite> <!-- com.adv.qa.selenium.tests.currency.phase2.A056_AP_Ledger_ControlsTest -->
